<?xml version="1.0"?>
<robot name="robot" xmlns:xacro="http://www.ros.org/wiki/xacro">
  <link name="base_footprint"/>
  <joint name="base_joint" type="fixed">
    <parent link="base_footprint"/>
    <child link="base_link"/>
    <origin xyz="0 0 0" rpy="0 0 0"/>
  </joint>
  <link name="base_link">
    <visual>
      <origin xyz="0 0 0" rpy="0 0 0"/>
      <geometry>
        <box size="4 2 0.5"/>
      </geometry>
      <material name="base_link-material">
        <color rgba="0.8713671191959567 0.3231432091022285 0.012286488353353374 1"/>
        <script>
          <uri>model://media/materials/scripts/gazebo.material</uri>
          <name>Gazebo/Orange</name>
        </script>
      </material>
    </visual>
    <collision>
      <origin xyz="0 0 0" rpy="0 0 0"/>
      <geometry>
        <box size="4 2 0.5"/>
      </geometry>
      <surface>
        <contact>
          <ode>
            <kp>100000</kp>
            <kd>10.0</kd>
          </ode>
        </contact>
        <friction>
          <ode>
            <mu>100.0</mu>
            <mu2>50.0</mu2>
          </ode>
        </friction>
      </surface>
    </collision>
    <inertial>
      <origin xyz="0 0 0" rpy="0 0 0"/>
      <mass value="100"/>
      <inertia ixx="35.0" ixy="0" ixz="0" iyy="95.0" iyz="0" izz="105.0"/>
    </inertial>
  </link>

  <joint name="base_link_to_front_left_steer" type="revolute">
    <parent link="base_link"/>
    <child link="front_left_steer_link"/>
    <origin xyz="1.3230052887669985 1.265027525157693 0" rpy="0 0 0"/>
    <axis xyz="0 0 1"/>
    <limit lower="-0.7854" upper="0.7854" effort="10" velocity="2.0"/>
    <dynamics damping="5.0" friction="0.1"/>
  </joint>
  <link name="front_left_steer_link">
    <visual>
      <origin xyz="0 0 0" rpy="0 0 0"/>
      <geometry>
        <box size="0.01 0.01 0.01"/>
      </geometry>
      <material name="front_left_steer-material">
        <color rgba="0.6 0.3 0.1 1"/>
        <script>
          <uri>model://media/materials/scripts/gazebo.material</uri>
          <name>Gazebo/Blue</name>
        </script>
      </material>
    </visual>
    <inertial>
      <origin xyz="0 0 0" rpy="0 0 0"/>
      <mass value="0.5"/>
      <inertia ixx="0.005" ixy="0" ixz="0" iyy="0.005" iyz="0" izz="0.005"/>
    </inertial>
  </link>
  <joint name="front_left_steer_to_wheel" type="continuous">
    <parent link="front_left_steer_link"/>
    <child link="cylinder0"/>
    <origin xyz="0 0 0" rpy="0 0 0"/>
    <axis xyz="0 1 0"/>
    <limit effort="10" velocity="10"/>
    <hardwareInterface>EffortJointInterface</hardwareInterface>
    <dynamics damping="0.5" friction="0.1"/>
  </joint>
  <link name="cylinder0">
    <visual>
      <origin xyz="0 0 0" rpy="-1.5708 0 0"/>
      <geometry>
        <cylinder radius="0.4" length="0.2"/>
      </geometry>
      <material name="cylinder0-material">
        <color rgba="0 0 0 1"/>
        <script>
          <uri>model://media/materials/scripts/gazebo.material</uri>
          <name>Gazebo/Black</name>
        </script>
      </material>
    </visual>
    <collision>
      <origin xyz="0 0 0" rpy="0 0 0"/>
      <geometry>
        <cylinder radius="0.5" length="1"/>
      </geometry>
    </collision>
    <inertial>
      <origin xyz="0 0 0" rpy="0 0 0"/>
      <mass value="5"/>
      <inertia ixx="0.2167" ixy="0" ixz="0" iyy="0.4" iyz="0" izz="0.2167"/>
    </inertial>
  </link>

  <joint name="base_link_to_front_right_steer" type="revolute">
    <parent link="base_link"/>
    <child link="front_right_steer_link"/>
    <origin xyz="1.35287 -1.30825 0" rpy="0 0 0"/>
    <axis xyz="0 0 1"/>
    <limit lower="-0.7854" upper="0.7854" effort="10" velocity="2.0"/>
    <dynamics damping="5.0" friction="0.1"/>
  </joint>
  <link name="front_right_steer_link">
    <visual>
      <origin xyz="0 0 0" rpy="0 0 0"/>
      <geometry>
        <box size="0.01 0.01 0.01"/>
      </geometry>
      <material name="front_right_steer-material">
        <color rgba="0.6 0.3 0.1 1"/>
        <script>
          <uri>model://media/materials/scripts/gazebo.material</uri>
          <name>Gazebo/Blue</name>
        </script>
      </material>
    </visual>
    <inertial>
      <origin xyz="0 0 0" rpy="0 0 0"/>
      <mass value="0.5"/>
      <inertia ixx="0.005" ixy="0" ixz="0" iyy="0.005" iyz="0" izz="0.005"/>
    </inertial>
  </link>
  <joint name="front_right_steer_to_wheel" type="continuous">
    <parent link="front_right_steer_link"/>
    <child link="cylinder3"/>
    <origin xyz="0 0 0" rpy="0 0 0"/>
    <axis xyz="0 1 0"/>
    <limit effort="10" velocity="10"/>
    <hardwareInterface>EffortJointInterface</hardwareInterface>
    <dynamics damping="0.5" friction="0.1"/>
  </joint>
  <link name="cylinder3">
    <visual>
      <origin xyz="0 0 0" rpy="-1.5708 0 0"/>
      <geometry>
        <cylinder radius="0.4" length="0.2"/>
      </geometry>
      <material name="cylinder3-material">
        <color rgba="0 0 0 1"/>
        <script>
          <uri>model://media/materials/scripts/gazebo.material</uri>
          <name>Gazebo/Black</name>
        </script>
      </material>
    </visual>
    <collision>
      <origin xyz="0 0 0" rpy="0 0 0"/>
      <geometry>
        <cylinder radius="0.5" length="1"/>
      </geometry>
    </collision>
    <inertial>
      <origin xyz="0 0 0" rpy="0 0 0"/>
      <mass value="5"/>
      <inertia ixx="0.2167" ixy="0" ixz="0" iyy="0.4" iyz="0" izz="0.2167"/>
    </inertial>
  </link>

  <joint name="base_link_to_cylinder1" type="continuous">
    <parent link="base_link"/>
    <child link="cylinder1"/>
    <origin xyz="-0.08616 1.27160 0" rpy="0 0 0"/>
    <axis xyz="0 1 0"/>
    <limit effort="10" velocity="10"/>
    <hardwareInterface>EffortJointInterface</hardwareInterface>
    <dynamics damping="0.5" friction="0.1"/>
  </joint>
  <link name="cylinder1">
    <visual>
      <origin xyz="0 0 0" rpy="-1.5708 0 0"/>
      <geometry>
        <cylinder radius="0.4" length="0.2"/>
      </geometry>
      <material name="cylinder1-material">
        <color rgba="0 0 0 1"/>
        <script>
          <uri>model://media/materials/scripts/gazebo.material</uri>
          <name>Gazebo/Black</name>
        </script>
      </material>
    </visual>
    <collision>
      <origin xyz="0 0 0" rpy="0 0 0"/>
      <geometry>
        <cylinder radius="0.5" length="1"/>
      </geometry>
    </collision>
    <inertial>
      <origin xyz="0 0 0" rpy="0 0 0"/>
      <mass value="5"/>
      <inertia ixx="0.2167" ixy="0" ixz="0" iyy="0.4" iyz="0" izz="0.2167"/>
    </inertial>
  </link>

  <joint name="base_link_to_cylinder2" type="continuous">
    <parent link="base_link"/>
    <child link="cylinder2"/>
    <origin xyz="-1.52679 1.23114 0" rpy="0 0 0"/>
    <axis xyz="0 1 0"/>
    <limit effort="10" velocity="10"/>
    <hardwareInterface>EffortJointInterface</hardwareInterface>
    <dynamics damping="0.5" friction="0.1"/>
  </joint>
  <link name="cylinder2">
    <visual>
      <origin xyz="0 0 0" rpy="-1.5708 0 0"/>
      <geometry>
        <cylinder radius="0.4" length="0.2"/>
      </geometry>
      <material name="cylinder2-material">
        <color rgba="0 0 0 1"/>
        <script>
          <uri>model://media/materials/scripts/gazebo.material</uri>
          <name>Gazebo/Black</name>
        </script>
      </material>
    </visual>
    <collision>
      <origin xyz="0 0 0" rpy="0 0 0"/>
      <geometry>
        <cylinder radius="0.5" length="1"/>
      </geometry>
    </collision>
    <inertial>
      <origin xyz="0 0 0" rpy="0 0 0"/>
      <mass value="5"/>
      <inertia ixx="0.2167" ixy="0" ixz="0" iyy="0.4" iyz="0" izz="0.2167"/>
    </inertial>
  </link>

  <joint name="base_link_to_cylinder4" type="continuous">
    <parent link="base_link"/>
    <child link="cylinder4"/>
    <origin xyz="-0.04911 -1.31088 0" rpy="0 0 0"/>
    <axis xyz="0 1 0"/>
    <limit effort="10" velocity="10"/>
    <hardwareInterface>EffortJointInterface</hardwareInterface>
    <dynamics damping="0.5" friction="0.1"/>
  </joint>
  <link name="cylinder4">
    <visual>
      <origin xyz="0 0 0" rpy="-1.5708 0 0"/>
      <geometry>
        <cylinder radius="0.4" length="0.2"/>
      </geometry>
      <material name="cylinder4-material">
        <color rgba="0 0 0 1"/>
        <script>
          <uri>model://media/materials/scripts/gazebo.material</uri>
          <name>Gazebo/Black</name>
        </script>
      </material>
    </visual>
    <collision>
      <origin xyz="0 0 0" rpy="0 0 0"/>
      <geometry>
        <cylinder radius="0.5" length="1"/>
      </geometry>
    </collision>
    <inertial>
      <origin xyz="0 0 0" rpy="0 0 0"/>
      <mass value="5"/>
      <inertia ixx="0.2167" ixy="0" ixz="0" iyy="0.4" iyz="0" izz="0.2167"/>
    </inertial>
  </link>

  <joint name="base_link_to_cylinder5" type="continuous">
    <parent link="base_link"/>
    <child link="cylinder5"/>
    <origin xyz="0 0 0" rpy="0 0 0"/>
    <axis xyz="0 1 0"/>
    <limit effort="10" velocity="10"/>
    <hardwareInterface>EffortJointInterface</hardwareInterface>
    <dynamics damping="0.5" friction="0.1"/>
  </joint>
  <link name="cylinder5">
    <visual>
      <origin xyz="0 0 0" rpy="1.5708 0 0"/>
      <geometry>
        <cylinder radius="0.1" length="0.3"/>
      </geometry>
      <material name="cylinder5-material">
        <color rgba="0 0 0 1"/>
        <script>
          <uri>model://media/materials/scripts/gazebo.material</uri>
          <name>Gazebo/Black</name>
        </script>
      </material>
    </visual>
    <collision>
      <origin xyz="0 0 0" rpy="0 0 0"/>
      <geometry>
        <cylinder radius="0.5" length="1"/>
      </geometry>
    </collision>
    <inertial>
      <origin xyz="0 0 0" rpy="0 0 0"/>
      <mass value="5"/>
      <inertia ixx="0.05" ixy="0" ixz="0" iyy="0.025" iyz="0" izz="0.05"/>
    </inertial>
  </link>

  <joint name="base_link_to_cylinder6" type="continuous">
    <parent link="base_link"/>
    <child link="cylinder6"/>
    <origin xyz="-0.06594 -1.11488 0" rpy="0 0 0"/>
    <axis xyz="0 1 0"/>
    <limit effort="10" velocity="10"/>
    <dynamics damping="0.5" friction="0.1"/>
  </joint>
  <link name="cylinder6">
    <visual>
      <origin xyz="0 0 0" rpy="1.5708 0 0"/>
      <geometry>
        <cylinder radius="0.1" length="0.3"/>
      </geometry>
      <material name="cylinder6-material">
        <color rgba="0 0 0 1"/>
        <script>
          <uri>model://media/materials/scripts/gazebo.material</uri>
          <name>Gazebo/Black</name>
        </script>
      </material>
    </visual>
    <collision>
      <origin xyz="0 0 0" rpy="0 0 0"/>
      <geometry>
        <cylinder radius="0.5" length="1"/>
      </geometry>
    </collision>
    <inertial>
      <origin xyz="0 0 0" rpy="0 0 0"/>
      <mass value="5"/>
      <inertia ixx="0.05" ixy="0" ixz="0" iyy="0.025" iyz="0" izz="0.05"/>
    </inertial>
  </link>

  <joint name="base_link_to_cylinder7" type="continuous">
    <parent link="base_link"/>
    <child link="cylinder7"/>
    <origin xyz="1.34329 -1.04882 0" rpy="0 0 0"/>
    <axis xyz="0 1 0"/>
    <limit effort="10" velocity="10"/>
    <dynamics damping="0.5" friction="0.1"/>
  </joint>
  <link name="cylinder7">
    <visual>
      <origin xyz="0 0 0" rpy="1.5708 0 0"/>
      <geometry>
        <cylinder radius="0.1" length="0.3"/>
      </geometry>
      <material name="cylinder7-material">
        <color rgba="0 0 0 1"/>
        <script>
          <uri>model://media/materials/scripts/gazebo.material</uri>
          <name>Gazebo/Black</name>
        </script>
      </material>
    </visual>
    <collision>
      <origin xyz="0 0 0" rpy="0 0 0"/>
      <geometry>
        <cylinder radius="0.5" length="1"/>
      </geometry>
    </collision>
    <inertial>
      <origin xyz="0 0 0" rpy="0 0 0"/>
      <mass value="5"/>
      <inertia ixx="0.05" ixy="0" ixz="0" iyy="0.025" iyz="0" izz="0.05"/>
    </inertial>
  </link>

  <joint name="base_link_to_cylinder8" type="continuous">
    <parent link="base_link"/>
    <child link="cylinder8"/>
    <origin xyz="-0.122244 1.10651 0" rpy="0 0 0"/>
    <axis xyz="0 1 0"/>
    <limit effort="10" velocity="10"/>
    <dynamics damping="0.5" friction="0.1"/>
  </joint>
  <link name="cylinder8">
    <visual>
      <origin xyz="0 0 0" rpy="1.5708 0 0"/>
      <geometry>
        <cylinder radius="0.1" length="0.3"/>
      </geometry>
      <material name="cylinder8-material">
        <color rgba="0 0 0 1"/>
        <script>
          <uri>model://media/materials/scripts/gazebo.material</uri>
          <name>Gazebo/Black</name>
        </script>
      </material>
    </visual>
    <collision>
      <origin xyz="0 0 0" rpy="0 0 0"/>
      <geometry>
        <cylinder radius="0.5" length="1"/>
      </geometry>
    </collision>
    <inertial>
      <origin xyz="0 0 0" rpy="0 0 0"/>
      <mass value="5"/>
      <inertia ixx="0.05" ixy="0" ixz="0" iyy="0.025" iyz="0" izz="0.05"/>
    </inertial>
  </link>

  <joint name="base_link_to_cylinder9" type="continuous">
    <parent link="base_link"/>
    <child link="cylinder9"/>
    <origin xyz="-1.51109 1.14690 0" rpy="0 0 0"/>
    <axis xyz="0 1 0"/>
    <limit effort="10" velocity="10"/>
    <dynamics damping="0.5" friction="0.1"/>
  </joint>
  <link name="cylinder9">
    <visual>
      <origin xyz="0 0 0" rpy="1.5708 0 0"/>
      <geometry>
        <cylinder radius="0.1" length="0.3"/>
      </geometry>
      <material name="cylinder9-material">
        <color rgba="0 0 0 1"/>
        <script>
          <uri>model://media/materials/scripts/gazebo.material</uri>
          <name>Gazebo/Black</name>
        </script>
      </material>
    </visual>
    <collision>
      <origin xyz="0 0 0" rpy="0 0 0"/>
      <geometry>
        <cylinder radius="0.5" length="1"/>
      </geometry>
    </collision>
    <inertial>
      <origin xyz="0 0 0" rpy="0 0 0"/>
      <mass value="5"/>
      <inertia ixx="0.05" ixy="0" ixz="0" iyy="0.025" iyz="0" izz="0.05"/>
    </inertial>
  </link>

  <joint name="base_link_to_cylinder10" type="continuous">
    <parent link="base_link"/>
    <child link="cylinder10"/>
    <origin xyz="1.29847 1.13963 0" rpy="0 0 0"/>
    <axis xyz="0 1 0"/>
    <limit effort="10" velocity="10"/>
    <dynamics damping="0.5" friction="0.1"/>
  </joint>
  <link name="cylinder10">
    <visual>
      <origin xyz="0 0 0" rpy="1.5708 0 0"/>
      <geometry>
        <cylinder radius="0.1" length="0.3"/>
      </geometry>
      <material name="cylinder10-material">
        <color rgba="0 0 0 1"/>
        <script>
          <uri>model://media/materials/scripts/gazebo.material</uri>
          <name>Gazebo/Black</name>
        </script>
      </material>
    </visual>
    <collision>
      <origin xyz="0 0 0" rpy="0 0 0"/>
      <geometry>
        <cylinder radius="0.5" length="1"/>
      </geometry>
    </collision>
    <inertial>
      <origin xyz="0 0 0" rpy="0 0 0"/>
      <mass value="5"/>
      <inertia ixx="0.05" ixy="0" ixz="0" iyy="0.025" iyz="0" izz="0.05"/>
    </inertial>
  </link>

  <joint name="base_link_to_cylinder11" type="continuous">
    <parent link="base_link"/>
    <child link="cylinder11"/>
    <origin xyz="-1.4936 -1.31376 0" rpy="0 0 0"/>
    <axis xyz="0 1 0"/>
    <limit effort="10" velocity="10"/>
    <dynamics damping="0.5" friction="0.1"/>
  </joint>
  <link name="cylinder11">
    <visual>
      <origin xyz="0 0 0" rpy="-1.5708 0 0"/>
      <geometry>
        <cylinder radius="0.4" length="0.2"/>
      </geometry>
      <material name="cylinder11-material">
        <color rgba="0 0 0 1"/>
        <script>
          <uri>model://media/materials/scripts/gazebo.material</uri>
          <name>Gazebo/Black</name>
        </script>
      </material>
    </visual>
    <collision>
      <origin xyz="0 0 0" rpy="0 0 0"/>
      <geometry>
        <cylinder radius="0.5" length="1"/>
      </geometry>
    </collision>
    <inertial>
      <origin xyz="0 0 0" rpy="0 0 0"/>
      <mass value="5"/>
      <inertia ixx="0.2167" ixy="0" ixz="0" iyy="0.4" iyz="0" izz="0.2167"/>
    </inertial>
  </link>

  <joint name="base_link_to_cylinder12" type="continuous">
    <parent link="base_link"/>
    <child link="cylinder12"/>
    <origin xyz="-1.48469 -1.10029 0" rpy="0 0 0"/>
    <axis xyz="0 1 0"/>
    <limit effort="10" velocity="10"/>
    <dynamics damping="0.5" friction="0.1"/>
  </joint>
  <link name="cylinder12">
    <visual>
      <origin xyz="0 0 0" rpy="1.5708 0 0"/>
      <geometry>
        <cylinder radius="0.1" length="0.3"/>
      </geometry>
      <material name="cylinder12-material">
        <color rgba="0 0 0 1"/>
        <script>
          <uri>model://media/materials/scripts/gazebo.material</uri>
          <name>Gazebo/Black</name>
        </script>
      </material>
    </visual>
    <collision>
      <origin xyz="0 0 0" rpy="0 0 0"/>
      <geometry>
        <cylinder radius="0.5" length="1"/>
      </geometry>
    </collision>
    <inertial>
      <origin xyz="0 0 0" rpy="0 0 0"/>
      <mass value="5"/>
      <inertia ixx="0.05" ixy="0" ixz="0" iyy="0.025" iyz="0" izz="0.05"/>
    </inertial>
  </link>

  <joint name="base_link_to_camera" type="fixed">
    <parent link="base_link"/>
    <child link="camera_link"/>
    <origin xyz="2 0 0.3" rpy="0 0 0"/>
  </joint>
  <link name="camera_link">
    <visual>
      <origin xyz="0 0 0" rpy="0 0 0"/>
      <geometry>
        <box size="0.1 0.1 0.1"/>
      </geometry>
      <material name="camera_material">
        <color rgba="0.5 0.5 0.5 1"/>
        <script>
          <uri>model://media/materials/scripts/gazebo.material</uri>
          <name>Gazebo/Gray</name>
        </script>
      </material>
    </visual>
    <collision>
      <origin xyz="0 0 0" rpy="0 0 0"/>
      <geometry>
        <box size="0.1 0.1 0.1"/>
      </geometry>
    </collision>
    <inertial>
      <origin xyz="0 0 0" rpy="0 0 0"/>
      <mass value="1"/>
      <inertia ixx="0.01" ixy="0" ixz="0" iyy="0.01" iyz="0" izz="0.01"/>
    </inertial>
  </link>
  <gazebo reference="camera_link">
    <sensor type="camera" name="camera_sensor">
      <always_on>true</always_on>
      <update_rate>10</update_rate>
      <camera>
        <horizontal_fov>1.047</horizontal_fov>
        <image>
          <width>640</width>
          <height>480</height>
          <format>R8G8B8</format>
        </image>
        <clip>
          <near>0.1</near>
          <far>100</far>
        </clip>
      </camera>
      <plugin name="gazebo_ros_camera" filename="libgazebo_ros_camera.so">
        <ros>
          <namespace>/camera</namespace>
          <remapping>image_raw:=/camera/image_raw</remapping>
          <remapping>camera_info:=/camera/camera_info</remapping>
        </ros>
        <frameName>camera_link</frameName>
        <cameraName>camera</cameraName>
      </plugin>
    </sensor>
  </gazebo>

  <joint name="base_link_to_laser" type="fixed">
    <parent link="base_link"/>
    <child link="laser_link"/>
    <origin xyz="2.0 0 0.3" rpy="0 0 0"/>
  </joint>
  <link name="laser_link">
    <visual>
      <origin xyz="0 0 0" rpy="0 0 0"/>
      <geometry>
        <box size="0.1 0.1 0.1"/>
      </geometry>
      <material name="laser_material">
        <color rgba="1 1 1 1"/>
      </material>
    </visual>
    <collision>
      <origin xyz="0 0 0" rpy="0 0 0"/>
      <geometry>
        <box size="0.1 0.1 0.1"/>
      </geometry>
    </collision>
    <inertial>
      <origin xyz="0 0 0" rpy="0 0 0"/>
      <mass value="0.1"/>
      <inertia ixx="0.01" ixy="0" ixz="0" iyy="0.01" iyz="0" izz="0.01"/>
    </inertial>
  </link>
  <gazebo reference="laser_link">
    <sensor type="ray" name="laser_sensor">
      <always_on>true</always_on>
      <update_rate>10</update_rate>
      <ray>
        <scan>
          <horizontal>
            <samples>720</samples>
            <resolution>1</resolution>
            <min_angle>-1.57</min_angle>
            <max_angle>1.57</max_angle>
          </horizontal>
        </scan>
        <range>
          <min>0.0</min>
          <max>10.0</max>
        </range>
        <noise>
          <type>gaussian</type>
          <mean>0.0</mean>
          <stddev>0.01</stddev>
        </noise>
      </ray>
      <plugin name="gazebo_ros_laser" filename="libgazebo_ros_laser.so">
        <ros>
          <namespace>/</namespace>
          <remapping>scan:=/scan</remapping>
        </ros>
        <frameName>laser_link</frameName>
        <topicName>/scan</topicName>
      </plugin>
    </sensor>
  </gazebo>

  <gazebo>
    <plugin name="planar_move" filename="libgazebo_ros_planar_move.so">
      <bodyName>base_link</bodyName>
      <topicName>cmd_vel</topicName>
      <maxVelX>1.0</maxVelX>
      <maxVelY>0.0</maxVelY>
      <maxVelTheta>1.0</maxVelTheta>
      <use_vel_topics>true</use_vel_topics>
    </plugin>
  </gazebo>
</robot>
